I'm sorry, but an uncaught exception occurred.

While running game code:
  File "game/week_one.rpy", line 138, in script
    character("Mom") "Hurry up!"
Exception: Sayer 'character("Mom")' is not defined.

-- Full Traceback ------------------------------------------------------------

Full traceback:
  File "game/week_one.rpy", line 138, in script
    character("Mom") "Hurry up!"
  File "C:\Users\lowda\Downloads\renpy-8.2.0-sdk.7z\renpy-8.2.0-sdk\renpy\ast.py", line 2557, in execute
    Say.execute(self)
  File "C:\Users\lowda\Downloads\renpy-8.2.0-sdk.7z\renpy-8.2.0-sdk\renpy\ast.py", line 575, in execute
    who = eval_who(self.who, self.who_fast)
  File "C:\Users\lowda\Downloads\renpy-8.2.0-sdk.7z\renpy-8.2.0-sdk\renpy\ast.py", line 464, in eval_who
    raise Exception("Sayer '%s' is not defined." % who)
Exception: Sayer 'character("Mom")' is not defined.

Windows-10-10.0.19045 AMD64
Ren'Py 8.2.0.24012702
International Serious Game 1.0
Thu Feb  8 02:17:32 2024
